Workbook

Sheet initial_search
A1: Publication Type | B1: Authors | C1: Book Authors | D1: Book Editors | E1: Book Group Authors | F1: Author Full Names | G1: Book Author Full Names | H1: Group Authors | I1: Article Title | J1: Source Title | K1: Book Series Title | L1: Book Series Subtitle | M1: Language | N1: Document Type | O1: Conference Title | P1: Conference Date | Q1: Conference Location | R1: Conference Sponsor | S1: Conference Host | T1: Author Keywords | U1: Keywords Plus | V1: Abstract | W1: Addresses | X1: Affiliations | Y1: Reprint Addresses | Z1: Email Addresses | AA1: Researcher Ids | AB1: ORCIDs | AC1: Funding Orgs | AD1: Funding Name Preferred | AE1: Funding Text | AF1: Cited References | AG1: Cited Reference Count | AH1: Times Cited, WoS Core | AI1: Times Cited, All Databases | AJ1: 180 Day Usage Count | AK1: Since 2013 Usage Count | AL1: Publisher | AM1: Publisher City | AN1: Publisher Address | AO1: ISSN | AP1: eISSN | AQ1: ISBN | AR1: Journal Abbreviation | AS1: Journal ISO Abbreviation | AT1: Publication Date | AU1: Publication Year | AV1: Volume | AW1: Issue | AX1: Part Number | AY1: Supplement | AZ1: Special Issue | BA1: Meeting Abstract | BB1: Start Page | BC1: End Page | BD1: Article Number | BE1: DOI | BF1: DOI Link | BG1: Book DOI | BH1: Early Access Date | BI1: Number of Pages | BJ1: WoS Categories | BK1: Web of Science Index | BL1: Research Areas | BM1: IDS Number | BN1: Pubmed Id | BO1: Open Access Designations | BP1: Highly Cited Status | BQ1: Hot Paper Status | BR1: Date of Export | BS1: UT (Unique WOS ID) | BT1: Web of Science Record
A2: J | B2: Li, X; Xu, F; Zhang, C; Che, T; Dai, LY; Zhang, YL | F2: Li, Xuan; Xu, Fan; Zhang, Chen; Che, Tao; Dai, Liyun; Zhang, Yanli | I2: Estimation of snow depth from AMSR-2 based on an AutoML method over the Qinghai-Tibet Plateau | J2: CRYOSPHERE | V2: Snow depth is a crucial parameter for describing the spatiotemporal variations of snow cover, and passive microwave snow depth products (10-25 km) are widely used for monitoring snow depth changes. However, as one of the three major snow-covered regions in China, the Qinghai-Tibet Plateau has complex terrain and rapid changes in snow cover with strong spatial heterogeneity, making it difficult for coarse-resolution snow depth products to accurately describe its spatiotemporal characteristics. This study proposes a high spatial resolution (500 m) snow depth estimation method based on the Advanced Microwave Scanning Radiometer 2 (AMSR-2) brightness temperature data and Automated Machine Learning. Firstly, using Pearson correlation coefficients, 19 key factors influencing snow depth, including AMSR-2 brightness temperature, slope, and surface roughness, were selected as input data (independent variables) for Automated Machine Learning. Meanwhile, passive microwave downscaled snow depth data and ground-based snow depth measurements were introduced as dependent variables for Automated Machine Learning. The Automated Machine Learning model was then trained separately for four different types of snow cover surfaces (forest, grassland, water, and bare land). Finally, through ten-fold cross-validation, the optimal machine learning model for snow depth estimation under each type of underlying surface coverage was selected, thus generating sequential snow depth datasets for the ten-year snow cover period of the Qinghai-Tibet Plateau from 2012 to 2021. Results show that (1) the estimated snow depth values well with ground-based observations, yielding a coefficient of determination (R-2) of 0.71 and a root mean square error (RMSE) of 3.64 cm, indicating high estimation accuracy. (2) Snow depth estimation demonstrates the highest accuracy in unused land (CatBoost, R-2 = 0.82), followed by grassland (CatBoost, R-2 = 0.77, RMSE = 3.11 cm), water (ET, R-2 = 0.75, RMSE = 2.20 cm), and forest (XGBoost, R-2 = 0.71, RMSE = 3.30 cm). (3) A comparison with snow cover extent derived from Landsat-8 optical imagery reveals that the estimated snow depth spatial distribution is consistent with snow cover extent, providing reliable data for monitoring snow cover changes in mountainous regions. | AO2: 1994-0416 | AP2: 1994-0424 | AU2: 2026 | AV2: 20 | AW2: 5 | BB2: 2977 | BC2: 2997 | BE2: 10.5194/tc-20-2977-2026 | BF2: =HYPERLINK("http://dx.doi.org/10.5194/tc-20-2977-2026","http://dx.doi.org/10.5194/tc-20-2977-2026") -> http://dx.doi.org/10.5194/tc-20-2977-2026 | BH2: MAY 2026 | BS2: WOS:001772482400001 | BT2: =HYPERLINK("https%3A%2F%2Fwww.webofscience.com%2Fwos%2Fwoscc%2Ffull-record%2FWOS:001772482400001","View Full Record in Web of Science") -> View Full Record in Web of Science
A3: J | B3: Ying, JJ; Yang, JW; Jiang, LM; Pan, JM; Xiong, C | F3: Ying, Jiajie; Yang, Jianwei; Jiang, Lingmei; Pan, Jinmei; Xiong, Chuan | I3: Scale patterns of the Sentinel-1 SAR-based snow depth product compared with station measurements and airborne LiDAR observations | J3: CRYOSPHERE | V3: Water storage in snowpacks in mountainous areas is critical for hydropower production, hydrological forecasting, and freshwater availability. Spaceborne synthetic aperture radar (SAR) is a powerful tool for quantitatively measuring snow mass because of its high spatial resolution and signal sensitivity to snow depth (SD). In particular, the first SAR SD product (C-snow) based on Sentinel-1 satellites displays high sensitivity to depolarization signals for dynamic SD monitoring in mountainous areas. Moreover, upscaled C-snow retrievals (e.g., 10 and 25 km) have been used to provide reference data to train machine learning models, improve passive microwave-based retrieval, and calibrate many hydrological models. However, to date, a systematic assessment of C-snow products at various scales has not been conducted. In this study, the performance of C-snow products at three scales (1, 10 and 25 km) is compared via station-based measurements and airborne LiDAR observations, and the scale patterns associated with the heterogeneity of the geographic environment and the representativeness of so-called true data are analyzed. The scale patterns of C-snow products vary across resolutions. They differ from the patterns observed in the station and airborne reference data. As the spatial scale increases from 1 to 25 km, the error of C-snow retrieval in reference to station measurements tends to increase (e.g., ubRMSE from 69.43 to 81.87 cm; bias from -8.89 to 11.66 cm), whereas it tends to decrease compared with Airborne Snow Observatory (ASO) data, with ubRMSE values ranging from 104.3 to 83.29 cm and bias values ranging from -91.31 to -52.73 cm. We also found that land cover types, e.g., tree cover and permanent ice, affect the C-snow product at various scales. Overestimation tends to occur in coarse pixels covered with even a small amount of permanent ice. The findings indicate that C-snow retrieval at three scales is characterized by high uncertainty. Therefore, researchers should focus on developing a robust SD retrieval algorithm by combining SAR backscattering signals and polarimetric and interferometric information. | AA3: ; Jiang, Lingmei/L-6099-2016 | AB3: 熊, 川/0000-0001-9164-4810; | AO3: 1994-0416 | AP3: 1994-0424 | AT3: JAN 14 | AU3: 2026 | AV3: 20 | AW3: 1 | BB3: 227 | BC3: 244 | BE3: 10.5194/tc-20-227-2026 | BF3: =HYPERLINK("http://dx.doi.org/10.5194/tc-20-227-2026","http://dx.doi.org/10.5194/tc-20-227-2026") -> http://dx.doi.org/10.5194/tc-20-227-2026 | BS3: WOS:001660928400001 | BT3: =HYPERLINK("https%3A%2F%2Fwww.webofscience.com%2Fwos%2Fwoscc%2Ffull-record%2FWOS:001660928400001","View Full Record in Web of Science") -> View Full Record in Web of Science
A4: J | B4: Bai, YN; Li, Z; Zhang, P; Zeng, JY; Huang, L; Qiao, HW; Gao, S; Hu, HD | F4: Bai, Yanan; Li, Zhen; Zhang, Ping; Zeng, Jiangyuan; Huang, Lei; Qiao, Haiwei; Gao, Shuo; Hu, Huadong | I4: A Snow Depth Retrieval Method Based on Super-Resolution Brightness Temperature Reconstruction and Multimodal Feature Synergy | J4: IEEE TRANSACTIONS ON GEOSCIENCE AND REMOTE SENSING | V4: Snow plays a critical role in the hydrological ecosystem of the Tibetan Plateau (TP), influencing both regional water availability and climate dynamics. Passive microwave remote sensing is a powerful tool for large-scale continuous snow depth (SD) monitoring, yet the low spatial resolution and saturation limitation of brightness temperature (TB) make it difficult for a single passive microwave dataset to address the challenges posed by the complex topography and fragmented snow distribution on the TP. To address this issue, an area-to-point downscaled daily SD retrieval method that accounts for spatial heterogeneity was proposed in this study using multimodal remote sensing data. First, we developed a new algorithm to reconstruct the high-resolution TB from Advanced Microwave Scanning Radiometer 2 (AMSR2), considering the effects of snow and land cover types. The recursive feature elimination (RFE) was used to select the optimal subset of features, including active and passive remote sensing information, meteorological data, and geographic factors, and then a multimodal feature-driven convolutional neural network (CNN)-long short-term memory network (LSTM) was used to retrieve daily 500-m SD data. The method effectively captures the dynamic spatial variation features of SD. The validation of the proposed TB reconstruction downscaling method using the enhanced-resolution TB data showed the RMSE ranged from 2.65 to 6.81 K at different frequencies. The contribution of multimodal features was analyzed based on SHapley Additive exPlanations (SHAP) values. Snow cover accumulation (SCA), H-pol TB at 89 GHz, and latitude were key features, although the relative contributions of these features varied significantly across different environments. In the site-based independent validation, the RMSE of the proposed method was 2.33 cm, demonstrating better accuracy than existing SD retrieval methods in the TP. The use of multimodal features improved accuracy by 1.67 cm (41.7%) compared to passive microwave features only. The proposed SD retrieval algorithm can obtain high-resolution and high-precision SD information, thereby supporting water resource management and climate change monitoring over the TP. | AA4: Zeng, Jiangyuan/AAJ-8512-2020 | AO4: 0196-2892 | AP4: 1558-0644 | AU4: 2026 | AV4: 64 | BD4: 4300615 | BE4: 10.1109/TGRS.2026.3653456 | BF4: =HYPERLINK("http://dx.doi.org/10.1109/TGRS.2026.3653456","http://dx.doi.org/10.1109/TGRS.2026.3653456") -> http://dx.doi.org/10.1109/TGRS.2026.3653456 | BS4: WOS:001708259200007 | BT4: =HYPERLINK("https%3A%2F%2Fwww.webofscience.com%2Fwos%2Fwoscc%2Ffull-record%2FWOS:001708259200007","View Full Record in Web of Science") -> View Full Record in Web of Science
A5: J | B5: Li, YX; Huang, XD; Ma, Y; Zhang, YH; Guo, QH; Liang, TG | F5: Li, Yuxin; Huang, Xiaodong; Ma, Ying; Zhang, Yonghui; Guo, Qianhao; Liang, Tiangang | I5: Persistent Reduction in Snow Mass Over China: Evidence From 40 Years of Satellite Observations | J5: IEEE TRANSACTIONS ON GEOSCIENCE AND REMOTE SENSING | V5: Snow water equivalent (SWE) serves as a key parameter for assessing snow hydrology, climate regulation, and water resource management. Despite its critical role, high spatiotemporal resolution SWE datasets remain limited, particularly for vast and topographically diverse regions such as China. Here, we present an innovative daily, 500-m resolution SWE dataset spanning 1980-2020 across China, developed through multisource remote sensing data fusion and machine learning (ML)-based downscaling. This dataset overcomes the spatiotemporal constraints inherent in conventional passive microwave (PMW) SWE retrievals. Validation with ground-based measurements yields an root mean square error (RMSE) of 10.85 mm, demonstrating its enhanced accuracy relative to existing products. Analysis of the dataset reveals a clear seasonal snow mass cycle in China, with a four-decade daily mean of 2.05 x 0(10) m(3) and peak values reaching 6.90 x 10(10) m(3) in January or February. Longitudinal trends indicate a significant and persistent decline in snow mass accumulation from 1980 to 2020. Furthermore, spatial variability analysis highlights marked regional differences in SWE trends during the snow season. This study advances the understanding of snow cover dynamics over China, offering a robust, highresolution SWE dataset with applications in snow hydrology, climate change studies, and water resource planning. | AA5: MA, Ying/KIB-0165-2024 | AO5: 0196-2892 | AP5: 1558-0644 | AU5: 2026 | AV5: 64 | BD5: 4300714 | BE5: 10.1109/TGRS.2026.3658511 | BF5: =HYPERLINK("http://dx.doi.org/10.1109/TGRS.2026.3658511","http://dx.doi.org/10.1109/TGRS.2026.3658511") -> http://dx.doi.org/10.1109/TGRS.2026.3658511 | BS5: WOS:001683260800023 | BT5: =HYPERLINK("https%3A%2F%2Fwww.webofscience.com%2Fwos%2Fwoscc%2Ffull-record%2FWOS:001683260800023","View Full Record in Web of Science") -> View Full Record in Web of Science
A6: J | B6: Brodylo, D; Bosche, LV; Busby, RR; Deeb, EJ; Douglas, TA; Lemmetyinen, J | F6: Brodylo, David; Bosche, Lauren V.; Busby, Ryan R.; Deeb, Elias J.; Douglas, Thomas A.; Lemmetyinen, Juha | I6: Object-based ensemble estimation of snow depth and snow water equivalent over multiple months in Sodankylä, Finland | J6: CRYOSPHERE | V6: Snowpack characteristics such as snow depth and snow water equivalent (SWE) are widely studied in regions prone to heavy snowfall and long winters. These features are measured in the field via manual or automated observations and over larger spatial scales with stand-alone remote sensing methods. However, individually these methods may struggle with accurately assessing snow depth and SWE in local spatial scales of several square kilometers. One method for leveraging the benefits of each individual dataset is to link field-based observations with high-resolution remote sensing imagery and then employ machine learning techniques to estimate snow depth and SWE across a broader geographic region. Here, we combined field-based repeat snow depth and SWE measurements over six instances from December 2022 to April 2023 in Sodankyl & auml;, Finland with Light Detection and Ranging (LiDAR) and WorldView-2 (WV-2) data to estimate snow depth, SWE, and snow density over a 10 km2 local scale study area. This was achieved with an object-based machine learning ensemble approach by first upscaling more numerous snow depth field data and then utilizing the estimated local scale snow depth to aid in estimating SWE over the study area. Snow density was then calculated from snow depth and SWE estimates. Snow depth peaked in March, SWE shortly after in early April, and snow density at the end of April. The ensemble-based approach had encouraging success with upscaling snow depth and SWE. Associations were also identified with carbon- and mineral-based forest surface soils, alongside dry and wet peatbogs. | AA6: Lemmetyinen, Juha/B-3739-2016; Brodylo, David/KVY-5799-2024 | AB6: Lemmetyinen, Juha/0000-0003-4434-9696; Brodylo, David/0000-0002-0331-2398 | AO6: 1994-0416 | AP6: 1994-0424 | AT6: NOV 24 | AU6: 2025 | AV6: 19 | AW6: 11 | BB6: 6127 | BC6: 6148 | BE6: 10.5194/tc-19-6127-2025 | BF6: =HYPERLINK("http://dx.doi.org/10.5194/tc-19-6127-2025","http://dx.doi.org/10.5194/tc-19-6127-2025") -> http://dx.doi.org/10.5194/tc-19-6127-2025 | BS6: WOS:001620513000001 | BT6: =HYPERLINK("https%3A%2F%2Fwww.webofscience.com%2Fwos%2Fwoscc%2Ffull-record%2FWOS:001620513000001","View Full Record in Web of Science") -> View Full Record in Web of Science
A7: J | B7: Kumawat, D; Ebtehaj, A; Kumar, S; Colliander, A | F7: Kumawat, Divya; Ebtehaj, Ardeshir; Kumar, Sujay; Colliander, Andreas | I7: Deep learning of seasonal peak snow water content of global boreal forest and arctic using spaceborne L-band radiometry | J7: REMOTE SENSING OF ENVIRONMENT | V7: Estimating peak snow water equivalent (SWE) across the Northern Hemisphere is critical for assessing seasonal water availability for both ecosystems and human needs. This study is the first to demonstrate a direct link between peak SWE and the temporal variability of L-band surface emission under a moderately dense vegetation canopy. We introduce SWEFormer, a novel deep transformer neural network that retrieves peak SWE primarily using time series of L-band brightness temperatures from NASA's Soil Moisture Active and Passive (SMAP) satellite. The model is trained using an incremental learning approach that transfers low-level information from reanalysis data for spatially coherent high-level learning from sparse in situ observations. SWEFormer outperforms leading global products, including ERA5, GlobSnow, and AMSR-based estimates, particularly in complex boreal watersheds, where previous global SWE estimates suffer from significant uncertainties, as vegetation canopy often markedly attenuates high-frequency microwave signatures of snowpack. | AA7: Kumar, Sujay/B-8142-2015; Colliander, Andreas/M-9864-2018; Kumawat, Divya/NAX-6725-2025 | AB7: Kumawat, Divya/0000-0002-7150-3954 | AO7: 0034-4257 | AP7: 1879-0704 | AT7: DEC 1 | AU7: 2025 | AV7: 330 | BD7: 114963 | BE7: 10.1016/j.rse.2025.114963 | BF7: =HYPERLINK("http://dx.doi.org/10.1016/j.rse.2025.114963","http://dx.doi.org/10.1016/j.rse.2025.114963") -> http://dx.doi.org/10.1016/j.rse.2025.114963 | BH7: AUG 2025 | BS7: WOS:001561289100003 | BT7: =HYPERLINK("https%3A%2F%2Fwww.webofscience.com%2Fwos%2Fwoscc%2Ffull-record%2FWOS:001561289100003","View Full Record in Web of Science") -> View Full Record in Web of Science
A8: J | B8: Demil, G; Haghighi, AT; Klove, B; Oussalah, M | F8: Demil, Getnet; Haghighi, Ali Torabi; Klove, Bjorn; Oussalah, Mourad | I8: Seeing through the clouds: enhanced snow and cloud segmentation in sentinel-2 imagery with mDeepLabV3+ | J8: EARTH SCIENCE INFORMATICS | V8: The application of satellite-based remote sensing has become increasingly prominent in snow hydrology parameter estimation, owing to its cost-efficiency, frequent revisit times, and broad spatial coverage. However, the presence of clouds introduces significant obstacles by obscuring features in optical satellite imagery. Differentiating snow from clouds remains challenging due to their similar color profiles and reflective properties. Conventional approaches, including manual thresholding, traditional machine learning techniques, and advanced deep learning models such as Convolutional Neural Networks (CNNs) and U-Net, have achieved only moderate success, despite remote sensing imagery's rich spatial and spectral data. To address this, we propose a novel deep-learning framework for classifying background, snow, and cloud regions in multispectral satellite imagery, based on a modified DeepLabV3+ architecture. Our approach incorporates an elevated dilation rate of 24 and leverages cross-domain transfer learning with ResNet-50 and ResNet-101 as backbone networks. Additionally, we utilized the Random Forest algorithm to evaluate the significance of spectral band features and support the semantic segmentation process. We also explored the impact of different input band combinations to determine the optimal configuration. Notably, the combination of Blue (Band 2), Short-Wave Infrared (Band 11), Red (Band 4), and Water Vapor (Band 9) with the ResNet-101 backbone outperformed all other tested configurations. This study provides a detailed assessment of the segmentation capabilities of modified DeepLabV3+ (mDeepLabV3+) models, using ResNet-50 (R50) and ResNet-101 (R101) backbones, on Sentinel-2 imagery for distinguishing cloud, snow, and background classes. Performance was benchmarked against established models, including Random Forest (RF), U-Net, and UCTNet, across various band combinations. Our results reveal that the mDeepLabV3+ model with the R50 backbone achieves exceptional precision (99.9%), F1 score (98.0%), and mean Intersection over Union (mIOU) of 91.13%, while the R101 variant excels in recall (97.8%) and overall accuracy (96.78%). These outcomes highlight the superior performance and reliability of the mDeepLabV3+ models for Sentinel-2 image segmentation. This work presents a robust and domain-adapted approach for snow and cloud segmentation in Sentinel-2 imagery, demonstrating improved accuracy over existing baselines. This thorough analysis offers critical insights into the efficacy of deep learning in such tasks, emphasizing opportunities for further refinement and practical implementation. | AA8: ; Haghighi, Ali/AAE-6862-2021 | AB8: Demil, Getnet/0009-0006-5158-0895; | AO8: 1865-0473 | AP8: 1865-0481 | AT8: JUL 28 | AU8: 2025 | AV8: 18 | AW8: 3 | BD8: 477 | BE8: 10.1007/s12145-025-01950-6 | BF8: =HYPERLINK("http://dx.doi.org/10.1007/s12145-025-01950-6","http://dx.doi.org/10.1007/s12145-025-01950-6") -> http://dx.doi.org/10.1007/s12145-025-01950-6 | BS8: WOS:001538089500001 | BT8: =HYPERLINK("https%3A%2F%2Fwww.webofscience.com%2Fwos%2Fwoscc%2Ffull-record%2FWOS:001538089500001","View Full Record in Web of Science") -> View Full Record in Web of Science
A9: J | B9: Cui, YR; Chen, SX; Mo, GQ; Ji, DB; Lv, LS; Fu, J | F9: Cui, Yurong; Chen, Sixuan; Mo, Guiquan; Ji, Dabin; Lv, Lansong; Fu, Juan | I9: Snow Depth Retrieval Using Sentinel-1 Radar Data: A Comparative Analysis of Random Forest and Support Vector Machine Models with Simulated Annealing Optimization | J9: REMOTE SENSING | V9: Snow plays a crucial role in global climate regulation, hydrological processes, and environmental change, making the accurate acquisition of snow depth data highly significant. In this study, we used Sentinel-1 radar data and employed a simulated annealing algorithm to select the optimal influencing factors from radar backscatter characteristics and spatiotemporal geographical parameters within the study area. Snow depth retrieval was subsequently performed using both random forest (RF) and Support Vector Machine (SVM) models. The retrieval results were validated against in situ measurements and compared with the long-term daily snow depth dataset of China for the period 2017-2019. The results indicate that the RF model achieves better agreement with the measured data than existing snow depth products. Specifically, in the Xinjiang region, the RF model demonstrates superior performance, with an R2 of 0.92, a root mean square error (RMSE) of 2.61 cm, and a mean absolute error (MAE) of 1.42 cm. In contrast, the SVM regression model shows weaker agreement with the observations, with an R2 lower than that of the existing snow depth product (0.51) in Xinjiang, and it performs poorly in other regions as well. Overall, the SVM model exhibits deficiencies in both predictive accuracy and spatial stability. This study provides a valuable reference for snow depth retrieval research based on active microwave remote sensing techniques. | AA9: Ji, Dabin/ADL-7793-2022 | AB9: 姬, 大彬/0000-0001-6388-2555 | AP9: 2072-4292 | AT9: JUL 24 | AU9: 2025 | AV9: 17 | AW9: 15 | BD9: 2584 | BE9: 10.3390/rs17152584 | BF9: =HYPERLINK("http://dx.doi.org/10.3390/rs17152584","http://dx.doi.org/10.3390/rs17152584") -> http://dx.doi.org/10.3390/rs17152584 | BS9: WOS:001549552300001 | BT9: =HYPERLINK("https%3A%2F%2Fwww.webofscience.com%2Fwos%2Fwoscc%2Ffull-record%2FWOS:001549552300001","View Full Record in Web of Science") -> View Full Record in Web of Science
A10: J | B10: Ying, J; Yang, J; Jiang, L; Pan, J; Zhang, C; Xiong, C; Shi, J | F10: Ying, J. J.; Yang, J. W.; Jiang, L. M.; Pan, J. M.; Zhang, C.; Xiong, C.; Shi, J. C. | I10: Evaluation of the Sentinel-1 SAR-based snow depth product over the Northern Hemisphere | J10: JOURNAL OF HYDROLOGY | V10: Active microwave remote sensing techniques, especially synthetic aperture radar (SAR), are valid tools for monitoring snow depth (SD) because of their high spatial resolution and day-night all-weather monitoring. The first SAR (C-band)-based SD product (C-snow), which covers all mountain ranges in the Northern Hemisphere, has been used as a reference dataset in many applications, such as building SD retrieval algorithms, acting as training samples for machine learning models, and improving passive microwave-based retrievals. However, the performance of the C-snow dataset over the Northern Hemisphere is unknown and remains to be evaluated. In this study, we integrated several ground-based SD datasets and also collected airborne lidar surveys (ASO) to assess the accuracy of C-snow SD retrievals. Moreover, we quantitatively analyzed the influence of various factors, such as landscape, terrain, dry/wet state, etc., on the SD retrievals. The results revealed that compared with ground-based SD measurements, the overall unbiased root mean square error (ubRMSE) and bias values of C-snow in the Northern Hemisphere ranged from 60.98 to 68.18 cm and-22.93 to-9.81 cm, respectively, with correlation coefficients ranging from 0.52 to 0.58. Compared with the ASO observations, the ubRMSE and bias were 107.2 cm and-91.72 cm, respectively. The performances of the C-snow product exhibited spatial differences due to the topography (elevation, terrain slope, and undulation), landcover types (especially ice and forest), wet snow and availability of time series Sentinel-1 observations (affecting the C-snow retrieval algorithm). Moreover, C-snow retrievals tend to underestimate the SD in the late snow season annually because of the decreasing snow index (SI) caused by wet snow or snow metamorphism, although the SD still increases. The performance analysis in this study will be useful for determining the dominant factors impacting SD retrievals, evaluating and building SD retrieval models, and understanding the spatiotemporal distribution and changes in snowpack in mountains. | AA10: ; Jiang, Lingmei/L-6099-2016 | AB10: 施, 建成/0000-0002-6163-2912; Jiang, Lingmei/0000-0002-9847-9034 | AO10: 0022-1694 | AP10: 1879-2707 | AT10: NOV | AU10: 2025 | AV10: 661 | AX10: A | BD10: 133593 | BE10: 10.1016/j.jhydrol.2025.133593 | BF10: =HYPERLINK("http://dx.doi.org/10.1016/j.jhydrol.2025.133593","http://dx.doi.org/10.1016/j.jhydrol.2025.133593") -> http://dx.doi.org/10.1016/j.jhydrol.2025.133593 | BH10: JUN 2025 | BS10: WOS:001504904400002 | BT10: =HYPERLINK("https%3A%2F%2Fwww.webofscience.com%2Fwos%2Fwoscc%2Ffull-record%2FWOS:001504904400002","View Full Record in Web of Science") -> View Full Record in Web of Science
A11: J | B11: Kesikoglu, MH | F11: Kesikoglu, Mustafa Hayri | I11: Enhancing Snow Detection through Deep Learning: Evaluating CNN Performance Against Machine Learning and Unsupervised Classification Methods | J11: WATER RESOURCES MANAGEMENT | V11: Snow cover is a crucial natural water resource that provides water storage. Monitoring snow cover is essential for sustainable water resource management. Accurate and efficient snow cover mapping is vital for water resource planning, flood control, and climate impact assessments. Remote sensing provides a cost-effective approach for monitoring snow cover dynamics, but classification accuracy remains a challenge. This study introduces a deep learning-based 1D convolutional neural network (1D CNN) approach for improved snow cover classification in mountainous regions utilizing Landsat 5 and 8 satellite images. The effectiveness of 1D CNN was compared with unsupervised classification (UC) methods (Normalized Difference Snow Index (NDSI), band ratio-based Red/Short wave infrared (R/SWIR), and Near infrared/Short wave infrared (NIR/SWIR)) and supervised machine learning classification methods (support vector machines (SVM) and classification and regression trees (CART)) in this research. The study was performed on Erciyes Mountain, Turkey, across four different years. Classifier performances were assessed using various quantitative (precision, recall, F-score, overall accuracy, kappa) and qualitative (mean squared error, Pearson correlation coefficient, structural similarity index measure, peak signal-to-noise ratio) evaluation metrics. Pairwise statistical analysis using McNemar's test revealed significant differences between 1D CNN and the other classifiers. The findings demonstrated that the 1D CNN approach outperformed all other methods in achieving the highest accuracy in snow cover classification. These results indicate the potential of deep learning for enhancing snow cover assessment and supporting more effective water resource management strategies and policy-making. | AA11: Kesikoglu, Mustafa Hayri/AAL-1358-2020 | AB11: Kesikoglu, Mustafa Hayri/0000-0001-5199-0815 | AO11: 0920-4741 | AP11: 1573-1650 | AT11: SEP | AU11: 2025 | AV11: 39 | AW11: 12 | BB11: 6053 | BC11: 6071 | BE11: 10.1007/s11269-025-04240-4 | BF11: =HYPERLINK("http://dx.doi.org/10.1007/s11269-025-04240-4","http://dx.doi.org/10.1007/s11269-025-04240-4") -> http://dx.doi.org/10.1007/s11269-025-04240-4 | BH11: MAY 2025 | BS11: WOS:001489326400001 | BT11: =HYPERLINK("https%3A%2F%2Fwww.webofscience.com%2Fwos%2Fwoscc%2Ffull-record%2FWOS:001489326400001","View Full Record in Web of Science") -> View Full Record in Web of Science
A12: J | B12: Bai, YN; Li, Z; Zhang, P; Huang, L; Gao, S; Qiao, HW; Liu, C; Liang, S; Hu, HD | F12: Bai, Yanan; Li, Zhen; Zhang, Ping; Huang, Lei; Gao, Shuo; Qiao, Haiwei; Liu, Chang; Liang, Shuang; Hu, Huadong | I12: High-resolution snow depth retrieval by passive microwave based on linear unmixing and machine learning stacking technique | J12: INTERNATIONAL JOURNAL OF APPLIED EARTH OBSERVATION AND GEOINFORMATION | V12: Accurate measurement of high-resolution snow depth (SD) is crucial for regional ecohydrology and climate studies. Passive microwave remote sensing is an effective technique for SD retrieval on global or regional scales. However, its low spatial resolution limits its application in various fields. Additionally, the complex effects of multiple factors in the microwave radiation process pose a significant challenge for accurate SD retrieval as SD increases. In this study, a high-resolution SD retrieval algorithm for passive microwave data was developed based on the linear unmixing method and machine learning (ML) stacking technique. Firstly, the 0.25 degrees AMSR2 brightness temperature data were downscaled to 0.01 degrees through linear unmixing. Then, combining the temporal and spatial features of the snowpack, the high-resolution SD was retrieved based on the ML stacking technique. This method combined the advantages of multiple base models for retrieving different depths of snow, which effectively improved the overall estimation performance of the algorithm. Compared with in situ observed SD at meteorological stations and field observation SD, the algorithm achieved an overall RMSE of 5.25 cm, which was lower than that of other coarse-resolution SD datasets and products, including the long-term series of daily SD dataset in China (7.40 cm), the ERA5-Land (9.71 cm), and JAXA AMSR2 Level 2 SD products (12.59 cm). Especially, it reduced the estimation error of deep snow with a depth exceeding 30 cm by 20.3 %, 21.5 %, and 24.9 %, respectively. | AA12: Liu, Chang/JCN-7173-2023 | AB12: , lizhen/0000-0003-3491-0697 | AO12: 1569-8432 | AP12: 1872-826X | AT12: APR | AU12: 2025 | AV12: 138 | BD12: 104467 | BE12: 10.1016/j.jag.2025.104467 | BF12: =HYPERLINK("http://dx.doi.org/10.1016/j.jag.2025.104467","http://dx.doi.org/10.1016/j.jag.2025.104467") -> http://dx.doi.org/10.1016/j.jag.2025.104467 | BH12: APR 2025 | BS12: WOS:001447293400001 | BT12: =HYPERLINK("https%3A%2F%2Fwww.webofscience.com%2Fwos%2Fwoscc%2Ffull-record%2FWOS:001447293400001","View Full Record in Web of Science") -> View Full Record in Web of Science
A13: J | B13: Wei, YL; Li, XF; Gu, LJ; Zheng, ZJ; Zheng, XM; Jiang, T | F13: Wei, Yanlin; Li, Xiaofeng; Gu, Lingjia; Zheng, Zhaojun; Zheng, Xingming; Jiang, Tao | I13: Snow depth inversion and mapping at 500 m resolution from 1980 to 2020 in Northeast China using radiative transfer model and machine learning | J13: INTERNATIONAL JOURNAL OF APPLIED EARTH OBSERVATION AND GEOINFORMATION | V13: Accurate snow cover parameter assessment and mapping at a fine resolution can have profound implications for our understanding of the planet's water balance and energy dynamics. Passive microwave (PMW) remote sensing is among the most effective methods for snow depth (SD) retrieval. However, significant uncertainties persist in SD retrieval and mapping due to snow characteristic variations, forest canopy interference, and low spatial resolution of PMW. To overcome these limitations, a novel method considering multiple influencing factors was proposed by integration a radiation transfer model with a machine learning model for SD retrieval, and a 500 m resolution SD dataset (NCSD) was generated for 1980-2020 in Northeast China by combining downscaling model. The validation against independent ground observations revealed that the MAE, RMSE, and R values for NCSD were 4.39 cm, 6.65 cm and 0.77, respectively. Compared to existing SD products, NCSD data effectively avoid mixed pixel issues, improved SD retrieval performance, and reveal more refined snow cover spatiotemporal patterns. Additionally, the NCSD results indicated that the annual average SD in Northeast China exhibited an increasing trend from 1980 to 2020 (0.26 cm/10a, p > 0.05). However, a notable inflection point occurred in 2000, and a subsequent decreasing trend occurred from 2000 to 2020 (0.49 cm/10a, p > 0.05). Overall, the creation of NCSD effectively filled the gap related to high-resolution SD data, and facilitated the development of hydrological studies and climate change at the basin scale. | AB13: Li, Xiaofeng/0000-0002-1799-844X; Gu, Lingjia/0000-0002-4909-2263 | AO13: 1569-8432 | AP13: 1872-826X | AT13: MAY | AU13: 2025 | AV13: 139 | BD13: 104533 | BE13: 10.1016/j.jag.2025.104533 | BF13: =HYPERLINK("http://dx.doi.org/10.1016/j.jag.2025.104533","http://dx.doi.org/10.1016/j.jag.2025.104533") -> http://dx.doi.org/10.1016/j.jag.2025.104533 | BH13: APR 2025 | BS13: WOS:001471822100001 | BT13: =HYPERLINK("https%3A%2F%2Fwww.webofscience.com%2Fwos%2Fwoscc%2Ffull-record%2FWOS:001471822100001","View Full Record in Web of Science") -> View Full Record in Web of Science
A14: J | B14: Goodarzi, MR; Barzkar, A; Sabaghzadeh, M; Ghanbari, M; Attar, NF | F14: Goodarzi, Mohammad Reza; Barzkar, Ali; Sabaghzadeh, Maryam; Ghanbari, Meysam; Attar, Nasrin Fathollahzadeh | I14: Uncertainty Analysis of Machine Learning Methods To Estimate Snow Water Equivalent Using Meteorological and Remote Sensing Data | J14: WATER RESOURCES MANAGEMENT | V14: A better understanding of regional water resources may help improve management of these resources. Snow is a resource that cannot be accurately measured. Research in this field has been increasing in recent years with the advancements in machine learning methods and satellite imagery. This research measured Snow Water Equivalent (SWE) using eight machine learning approaches; Furthermore, the input data used in this study are monthly. Ten meteorological parameters related to snow, and also two parameters for albedo and snow cover fraction obtained from satellite imagery from 1981 to 2022, were provided as inputs to the models. The best input combination was determined through the gamma test, and the impact percentage of each input on the result was evaluated using sensitivity analysis. The results showed that the XGBoost (XGB) method with a Nash-Sutcliffe Efficiency (NSE) coefficient of 0.99 is the best, and Ridge regression with an NSE coefficient value of 0.6486 has the worst result. The dataset was divided into 80% for training and 20% for testing. The trend of snow water equivalent (SWE) during this period was evaluated utilizing the Mann-Kendall test and Sen's slope analysis. The findings indicate a decreasing trend in SWE. The utilization of current machine learning methods helps a more precise estimation of the water volume in the region, providing improved decision-making for the management of regional water resources. | AA14: Goodarzi, Mohammad/AAQ-3253-2020; Ghanbari, Meysam/PRR-2115-2026; Fathollahzadeh Attar, Nasrin/P-6175-2017 | AB14: Fathollahzadeh Attar, Nasrin/0000-0002-9506-452X | AO14: 0920-4741 | AP14: 1573-1650 | AT14: JUL | AU14: 2025 | AV14: 39 | AW14: 9 | BB14: 4471 | BC14: 4491 | BE14: 10.1007/s11269-025-04164-z | BF14: =HYPERLINK("http://dx.doi.org/10.1007/s11269-025-04164-z","http://dx.doi.org/10.1007/s11269-025-04164-z") -> http://dx.doi.org/10.1007/s11269-025-04164-z | BH14: APR 2025 | BS14: WOS:001459610300001 | BT14: =HYPERLINK("https%3A%2F%2Fwww.webofscience.com%2Fwos%2Fwoscc%2Ffull-record%2FWOS:001459610300001","View Full Record in Web of Science") -> View Full Record in Web of Science
A15: J | B15: Esfahani, AG; Moradizadeh, M; Srivastava, PK | F15: Esfahani, Ali Ghofrani; Moradizadeh, Mina; Srivastava, Prashant K. | I15: Improving AMSR2-derived Snow Depth Spatial Resolution Through Synergistic Combination of Machine Learning and Random Sets Over the European Alps | J15: PFG-JOURNAL OF PHOTOGRAMMETRY REMOTE SENSING AND GEOINFORMATION SCIENCE | V15: Snow depth is a critical parameter for meteorological, climatological, and hydrological models, enhancing regional water resource information and weather prediction accuracy. AMSR2 passive microwave data with 10-kilometer spatial resolution results in high error and uncertainty in snow depth estimation. This study attempted to develop machine learning algorithms to downscale AMSR2 snow depth data to 1 kilometer spatial resolution. One of the primary factors inflicting errors in snow depth downscaling is the absence of proper identification of snow-covered area boundaries (mixed pixels), leading to extensional uncertainty. In the present study, a novel method based on the theory of random sets has been developed to resolve the issue of mixed pixels in the boundaries of snow-covered areas for the European Alps. In addition to snow cover data acquired from random sets, auxiliary data for developing and training machine learning algorithms comprises of the Digital Elevation Model (DEM), Land Surface Temperature (LST), and Land Cover Type data were processed. The machine learning algorithms employed includes Support Vector Regression (SVR), Multi-Layer Perceptron (MLP), and Random Forest (RF). The RF algorithm, when considering snow cover data derived from random sets method, confirmed the excellent performance among the SVR and MLP algorithms. Using RF, the RMSE decreased from 31.67-16.34 cm, the correlation coefficient increased from 0.312-0.81, and the relative error decreased from 9.85-0.52% (reduced error and increased accuracy). The results based on evaluation metrics indicates an outstanding performance of the proposed innovative method for downscaling of AMSR2 snow depth. | AA15: /O-2815-2019 | AO15: 2512-2789 | AP15: 2512-2819 | AT15: JUN | AU15: 2025 | AV15: 93 | AW15: 3 | BB15: 231 | BC15: 250 | BE15: 10.1007/s41064-025-00338-x | BF15: =HYPERLINK("http://dx.doi.org/10.1007/s41064-025-00338-x","http://dx.doi.org/10.1007/s41064-025-00338-x") -> http://dx.doi.org/10.1007/s41064-025-00338-x | BH15: APR 2025 | BS15: WOS:001459026000001 | BT15: =HYPERLINK("https%3A%2F%2Fwww.webofscience.com%2Fwos%2Fwoscc%2Ffull-record%2FWOS:001459026000001","View Full Record in Web of Science") -> View Full Record in Web of Science
A16: J | B16: Demil, G; Haghighi, AT; Klöve, B; Oussalah, M | F16: Demil, Getnet; Haghighi, Ali Torabi; Klove, Bjorn; Oussalah, Mourad | I16: Advances in image-based estimation of snow variable: A systematic literature review on recent studies | J16: JOURNAL OF HYDROLOGY | V16: Accurately estimating snow hydrology parameters, including snow coverage mapping and snow depth, plays a significant role in comprehending water resource dynamics, flood forecasting, and environmental management in regions influenced by snow cover. These parameters are critical for hydrological models that simulate snowmelt and runoff, which are essential for predicting water availability and managing water resources in snow-covered areas. Traditional methods for estimating these parameters often rely on manual measurements or simplistic models, which can be inadequate for capturing the complexity of snow-related processes. In recent years, there has been a growing interest in leveraging deep learning techniques for snow hydrology parameter estimation, offering the potential to overcome these limitations. This review paper comprehensively analyzes the current state, challenges, and future directions of image-based approaches in snow hydrology parameter estimation. By harnessing the power of automated methods, particularly deep learning, these approaches demonstrate the ability to capture intricate spatial and temporal relationships present in image data. A comparative analysis on image-based methods highlights the strengths of automated approaches, including scalability and accuracy. Integration of image sensors, such as satellite imagery and crowd-sourced data, is explored as a crucial component of snow hydrology parameter estimation. Various satellite image sources, including Sentinel 1-2, Landsat, and Moderate Resolution Imaging Spectroradiometer (MODIS), are discussed in terms of their suitability for snow hydrological applications. Despite the promise of image-based approaches, challenges remain, including data availability, model interpretability, and transferability. The paper identifies future research directions, emphasizing the exploration of novel deep learning architectures and uncertainty quantification techniques to address these challenges. In conclusion, this review underscores the importance of image-based approaches for advancing snow hydrology parameter estimation. By addressing challenges and maximizing potential impact, these approaches have the potential to revolutionize snow hydrological modeling and environmental management. | AA16: ; Haghighi, Ali/AAE-6862-2021 | AB16: Klöve, Björn/0000-0002-2353-1440; Demil, Getnet/0009-0006-5158-0895; Oussalah, Mourad/0000-0002-4422-8723 | AO16: 0022-1694 | AP16: 1879-2707 | AT16: JUN | AU16: 2025 | AV16: 654 | BD16: 132855 | BE16: 10.1016/j.jhydrol.2025.132855 | BF16: =HYPERLINK("http://dx.doi.org/10.1016/j.jhydrol.2025.132855","http://dx.doi.org/10.1016/j.jhydrol.2025.132855") -> http://dx.doi.org/10.1016/j.jhydrol.2025.132855 | BH16: FEB 2025 | BS16: WOS:001433637500001 | BT16: =HYPERLINK("https%3A%2F%2Fwww.webofscience.com%2Fwos%2Fwoscc%2Ffull-record%2FWOS:001433637500001","View Full Record in Web of Science") -> View Full Record in Web of Science
A17: J | B17: Tanniru, S; Singh, DK; Singh, KK; Ramsankaran, R | F17: Tanniru, Srinivasarao; Singh, Dhiraj Kumar; Singh, Kamal Kant; Ramsankaran, Raaj | I17: Exploring Machine Learning's Potential for Estimating High Resolution Daily Snow Depth in Western Himalaya Using Passive Microwave Remote Sensing Data Sets | J17: EARTH AND SPACE SCIENCE | V17: Snow depth (SD) exhibits high spatiotemporal heterogeneity in Western Himalaya (WH), and its knowledge is essential for applications related to water resources, disaster management, climate, etc. However, due to inclement weather and rugged topographical conditions, only a sparse network of SD monitoring stations exists in WH. Spaceborne passive microwave (PMW) remote sensing data sets provides valuable information about SD; however, only a limited PMW SD studies that cover subregions of WH are available. Different machine learning (ML) methods viz. support vector machine, random forest, and Extremely Randomized Trees (ERT) were tested for estimating SD. Based on our preliminary assessment of these ML approaches, the current study utilizes ERT approach to estimate daily SD over the entire WH region. The ERT SD model is developed using PMW brightness temperature data sets from Advanced Microwave Scanning Radiometer-2 (AMSR-2), snow cover duration (SCD), and other auxiliary parameters (i.e., location, elevation, vegetation cover, etc.) during the winter period between 2012-2013 and 2019-2020. The data between 2012-2013 and 2017-2018 is used for training the model, whereas the data between 2018-2019 and 2019-2020 is used for testing the model. The results demonstrate: (a) The ERT SD model has shown improved SD estimates compared to the available PMW remote sensing-based operational SD products and empirical PMW SD models. (b) In general, with an increase in SD, the mean absolute error of SD retrievals has increased in all SD products/models. (c) Unlike the operational AMSR2 SD product, and Northern Hemisphere Machine Learning SD product, the ERT SD model retrievals have shown better consistency with MODIS snow cover. (d) The developed model has shown a wider range in SD retrievals as compared to other products considered in this study. | AA17: Tanniru, Srinivasarao/F-1862-2013; Ramsankaran, RAAJ/B-9198-2008 | AB17: Ramsankaran, RAAJ/0000-0001-8602-1934 | AP17: 2333-5084 | AT17: FEB 12 | AU17: 2025 | AV17: 12 | AW17: 2 | BD17: e2024EA003849 | BE17: 10.1029/2024EA003849 | BF17: =HYPERLINK("http://dx.doi.org/10.1029/2024EA003849","http://dx.doi.org/10.1029/2024EA003849") -> http://dx.doi.org/10.1029/2024EA003849 | BS17: WOS:001467218000001 | BT17: =HYPERLINK("https%3A%2F%2Fwww.webofscience.com%2Fwos%2Fwoscc%2Ffull-record%2FWOS:001467218000001","View Full Record in Web of Science") -> View Full Record in Web of Science
A18: J | B18: Hu, HH; He, L; Hui, FM; Cheng, X; Zheng, ZJ; Che, T; Chen, ZQ | F18: Hu, Haihan; He, Lian; Hui, Fengming; Cheng, Xiao; Zheng, Zhaojun; Che, Tao; Chen, Zhuoqi | I18: Snow Cover Mapping From Chinese Geostationary Meteorological Satellite FY-2F VISSR-II Data Using Random Forest Classifier | J18: IEEE JOURNAL OF SELECTED TOPICS IN APPLIED EARTH OBSERVATIONS AND REMOTE SENSING | V18: Accurate monitoring of snow cover is essential for understanding climate dynamics and supporting hydrological and environmental management. The Fengyun-2F (FY-2F) satellite is one of China's first geostationary meteorological satellites, equipped with the Stretched Visible and Infrared Spin Scan Radiometer-II (VISSR-II), which provides moderate-resolution imagery at high temporal resolution but has only five spectral channels. To enhance the snow cover mapping capability of the FY-2F VISSR-II sensor, this study develops a novel algorithm in which multitemporal observations within a single day are first fused to generate a daily synthesis image, thereby reducing cloud contamination. Based on this synthesized image, snow cover detection is then carried out using a random forest model driven by multisource spatiotemporal features. The algorithm was rigorously evaluated against in situ snow depth observations, Landsat 8 snow cover maps, Moderate Resolution Imaging Spectroradiometer (MODIS) snow cover products, and Fengyun-4 (FY-4) A snow cover product. The results indicate strong performance of the FY-2F snow cover product, with an overall accuracy (OA) of 90.8% and an F1-score (FS) of 88.9% against in situ measurements, and an OA of 94.6% with an FS of 91.9% compared to Landsat 8 snow cover maps. When validated against the four MODIS-based reference products and FY-4 A snow cover product, the FY-2F snow cover product achieved OA values ranging from 92% to 99%. The novelty of this work lies in the effective integration of auxiliary data to compensate for the limited bands. It provides a valuable reference for snow cover mapping from early geostationary meteorological satellites with a limited number of spectral bands. | AA18: He, Lian/AAF-3997-2020; Che, Tao/K-7136-2013 | AB18: He, Lian/0000-0002-9909-6107; Cheng, Xiao/0000-0001-6910-6565; Hu, Haihan/0009-0006-6101-6155; ZHENG, Zhaojun/0000-0002-7331-1905; Che, Tao/0000-0001-6848-7271 | AO18: 1939-1404 | AP18: 2151-1535 | AU18: 2025 | AV18: 18 | BB18: 27979 | BC18: 27992 | BE18: 10.1109/JSTARS.2025.3626728 | BF18: =HYPERLINK("http://dx.doi.org/10.1109/JSTARS.2025.3626728","http://dx.doi.org/10.1109/JSTARS.2025.3626728") -> http://dx.doi.org/10.1109/JSTARS.2025.3626728 | BS18: WOS:001626465700006 | BT18: =HYPERLINK("https%3A%2F%2Fwww.webofscience.com%2Fwos%2Fwoscc%2Ffull-record%2FWOS:001626465700006","View Full Record in Web of Science") -> View Full Record in Web of Science
A19: C | B19: Kumawat, D; Ehtehaj, A | E19: IEEE | F19: Kumawat, Divya; Ehtehaj, Ardeshir | I19: CAN DEEP TRANSFORMERS LEARN GLOBAL PEAK SNOW WATER EQUIVALENT FROM L-BAND SURFACE EMISSIONS? | J19: IGARSS 2025-2025 IEEE INTERNATIONAL GEOSCIENCE AND REMOTE SENSING SYMPOSIUM | K19: IEEE International Symposium on Geoscience and Remote Sensing IGARSS | O19: 2025 International Geoscience and Remote Sensing Symposium-IGARSS-Annual | P19: AUG 03-08, 2025 | Q19: Brisbane, AUSTRALIA | R19: Institute of Electrical and Electronics Engineers Inc | V19: The seasonal peak snow water equivalent (SWEp) is a key parameter for spring streamflow prediction, hydroelectricity generation, drought management, and ecosystem productivity. For the first time, this study proposes a novel methodology for estimating SWEp through learning from the coincident time series of L-band brightness temperature (TB) from the Soil Moisture Active Passive (SMAP) satellite (inputs) as well as reanalysis data and ground-based observations (outputs). This approach uses a deep transformer neural network, leveraging dynamic and static predictors through a multi-head self-attention mechanism, called SWEFormer. This methodology is enriched by the concept of transfer learning that incrementally learns and combines the information content of ERA5 reanalysis data with sparse ground observations, addressing data limitations and improving accuracy. Validation against in situ observations shows promising performance metrics with root mean squared error, bias, and coefficient of determination of 65.76 mm, 21.77 mm, and 0.65, nearly three times better than ERA5 estimates. Unlike methodologies relying on higher microwave frequencies with a low-penetration depth in vegetated areas, SWEFormer provides a robust, all-weather solution for SWEp estimation, supporting ecosystem modeling in high-latitude watersheds and boreal forest regions, where the human population relies on snowmelt-driven spring streamflow. | AA19: Kumawat, Divya/NAX-6725-2025 | AO19: 2153-6996 | AQ19: 979-8-3315-0811-1; 979-8-3315-0810-4 | AU19: 2025 | BB19: 727 | BC19: 732 | BE19: 10.1109/IGARSS55030.2025.11242584 | BF19: =HYPERLINK("http://dx.doi.org/10.1109/IGARSS55030.2025.11242584","http://dx.doi.org/10.1109/IGARSS55030.2025.11242584") -> http://dx.doi.org/10.1109/IGARSS55030.2025.11242584 | BS19: WOS:001697407700156 | BT19: =HYPERLINK("https%3A%2F%2Fwww.webofscience.com%2Fwos%2Fwoscc%2Ffull-record%2FWOS:001697407700156","View Full Record in Web of Science") -> View Full Record in Web of Science
A20: J | B20: Yan, YC; Qin, Y; Liu, YQ; Qiu, YB; Liu, Y | F20: Yan, Yongchang; Qin, Yan; Liu, Yongqiang; Qiu, Yubao; Liu, Yang | I20: Estimation of Moderate-Resolution Snow Depth in Xinjiang With Enhanced-Resolution Passive Microwave and Reanalysis Data by Machine Learning Methods | J20: IEEE JOURNAL OF SELECTED TOPICS IN APPLIED EARTH OBSERVATIONS AND REMOTE SENSING | V20: The integration of multisource data into the passive microwave retrieval of snow depth (SD) is vital for accurately capturing large-scale distribution of SD. However, the exiting SD retrieval algorithms overlook the impact of snow characteristics on brightness temperature, leading to inadequate representation of SD in complex regions. Therefore, this study constructs and optimizes SD retrieval models using four machine learning algorithms, including extreme gradient boosting (XGBoost), light gradient-boosting machine (LightGBM), categorical boosting (CatBoost), and random forest (RF) combing enhanced-resolution passive microwave data. A variety of variables are integrated into the models, encompassing geolocation, topographic indices, land cover, and snow characteristics (fractional snow cover, snow density, and snow grain size) sourced from ERA5-land reanalysis data. This approach focuses on accurately estimating the spatiotemporal distribution of SD over Xinjiang, characterized by dry-cold snow. The results indicate that First, upon incorporating auxiliary variables, the SD from the CatBoost model demonstrated superior performances over the other algorithms ($R<^>{2}$: CatBoost > LightGBM > XGBoost > RF). Second, the SD product from the CatBoost model exhibits interannual fluctuations. It slightly overestimates shallow snow (SD < 20 cm) and underestimates deep snow (SD > 20 cm). Third, the SD product reveals the spatial differentiation. Areas in northern Xinjiang with high value for SD (SD > 20 cm) are mainly distributed in the Tianshan Mountains and Altai Mountains. In contrast, the southern Xinjiang with high value for SD (SD > 10 cm) is largely clustered in the high-elevation regions surrounding the Kunlun Mountains. The findings highlight that employing this approach can lead to the establishment of valuable long-term SD datasets for capturing SD distribution. | AA20: ; Qiu, Yubao/P-8103-2016 | AB20: 邱, 玉宝/0000-0003-1313-6313; Yan, Yongchang/0009-0003-2667-5778; | AO20: 1939-1404 | AP20: 2151-1535 | AU20: 2025 | AV20: 18 | BB20: 11250 | BC20: 11262 | BE20: 10.1109/JSTARS.2025.3562216 | BF20: =HYPERLINK("http://dx.doi.org/10.1109/JSTARS.2025.3562216","http://dx.doi.org/10.1109/JSTARS.2025.3562216") -> http://dx.doi.org/10.1109/JSTARS.2025.3562216 | BS20: WOS:001484675600007 | BT20: =HYPERLINK("https%3A%2F%2Fwww.webofscience.com%2Fwos%2Fwoscc%2Ffull-record%2FWOS:001484675600007","View Full Record in Web of Science") -> View Full Record in Web of Science
A21: C | B21: Zheng, YF; Jiang, LM; Pan, FB | E21: IEEE | F21: Zheng, Yifei; Jiang, Lingmei; Pan, Fangbo | I21: An Improved AVHRR Fractional Snow Cover Mapping Algorithm Using MODIS Observations Combined with Time-Scale Decomposition | J21: IGARSS 2025-2025 IEEE INTERNATIONAL GEOSCIENCE AND REMOTE SENSING SYMPOSIUM | K21: IEEE International Symposium on Geoscience and Remote Sensing IGARSS | O21: 2025 International Geoscience and Remote Sensing Symposium-IGARSS-Annual | P21: AUG 03-08, 2025 | Q21: Brisbane, AUSTRALIA | R21: Institute of Electrical and Electronics Engineers Inc | V21: Long-term fractional snow cover (FSC) data is a critical input for hydrological, climatic, and energy balance models, making its monitoring essential for understanding global climate and hydrological processes. AVHRR, as a unique long-term remote sensing sensor, provides valuable snow cover data, but its low spatial resolution and limited spectral bands present challenges for accurate snow cover retrieval. To overcome these challenges, this study proposes an improved AVHRR FSC mapping algorithm by combining time-scale decomposition with XG Boost, using MODIS observations to enhance spatial resolution and accuracy. The model generates AVHRR FSC products with 500 m resolution, significantly improving FSC accuracy compared to the original AVHRR data, with RMSE reduced from 0.196 to 0.107. These results highlight the potential of AVHRR in long-term snow cover monitoring and the benefit of combining machine learning and higher-resolution data. | AA21: Jiang, Lingmei/L-6099-2016; Pan, Fangbo/IQU-2803-2023 | AO21: 2153-6996 | AQ21: 979-8-3315-0811-1; 979-8-3315-0810-4 | AU21: 2025 | BB21: 2366 | BC21: 2370 | BE21: 10.1109/IGARSS55030.2025.11243237 | BF21: =HYPERLINK("http://dx.doi.org/10.1109/IGARSS55030.2025.11243237","http://dx.doi.org/10.1109/IGARSS55030.2025.11243237") -> http://dx.doi.org/10.1109/IGARSS55030.2025.11243237 | BS21: WOS:001697407700498 | BT21: =HYPERLINK("https%3A%2F%2Fwww.webofscience.com%2Fwos%2Fwoscc%2Ffull-record%2FWOS:001697407700498","View Full Record in Web of Science") -> View Full Record in Web of Science
A22: J | B22: Liu, Y; Yang, JM; Chen, X; Yao, JQ; Li, LH; Qiu, YB | F22: Liu, Yang; Yang, Jinming; Chen, Xi; Yao, Junqiang; Li, Lanhai; Qiu, Yubao | I22: Moderate-resolution snow depth product retrieval from passive microwave brightness data over Xinjiang using machine learning approach | J22: INTERNATIONAL JOURNAL OF DIGITAL EARTH | V22: Passive microwave (PM) remote sensing have been extensively used for snow depth (SD) estimation. However, current SD products from traditional PM data fail to capture the differentiation in mountainous and complex terrains with coarse resolution. Therefore, this study incorporates factors such as geographical location, topographic features, and land cover, along with various machine learning algorithms including Gaussian process regression (GPR), support vector machine (SVM), random forest (RF), extreme gradient boosting (XGBoost), and light gradient boosting machine (LightGBM), to construct and optimize SD estimation using enhanced-resolution PM data. The results demonstrate the following: (1)With the auxiliary variables, the SD product from LightGBM-based models exhibits the highest accuracy. (2)The performance of SD products from the LightGBM-based model varies monthly and annually, with shallow snow cover being slightly overestimated (30 cm). (3)The reliable SD product indicates spatial distribution characteristics in Xinjiang, with regions demonstrating no significant improvement being larger than those with no significant degradation. The above results illustrate the remarkable advantages of machine learning in capturing SD distribution and its spatio-temporal variation bolstered by enhanced PM data and auxiliary data. | AA22: Li, Lanhai/AAE-9967-2020; Qiu, Yubao/P-8103-2016; yang, jinming/IWL-8395-2023 | AB22: yang, jinming/0000-0002-1843-6908 | AO22: 1753-8947 | AP22: 1753-8955 | AT22: DEC 31 | AU22: 2024 | AV22: 17 | AW22: 1 | BD22: 2299208 | BE22: 10.1080/17538947.2023.2299208 | BF22: =HYPERLINK("http://dx.doi.org/10.1080/17538947.2023.2299208","http://dx.doi.org/10.1080/17538947.2023.2299208") -> http://dx.doi.org/10.1080/17538947.2023.2299208 | BS22: WOS:001135343300001 | BT22: =HYPERLINK("https%3A%2F%2Fwww.webofscience.com%2Fwos%2Fwoscc%2Ffull-record%2FWOS:001135343300001","View Full Record in Web of Science") -> View Full Record in Web of Science
